Workbook
Name Slicer_Channel: #N/A
Name Slicer_Country: #N/A
Name Slicer_Order_Month: #N/A
Name Slicer_ProductCategory: #N/A
Name Slicer_Region: #N/A
Name Slicer_Region1: #N/A
Name Slicer_Salesperson: #N/A
Name Slicer_Salesperson1: #N/A

Sheet Original Data
A1: OrderID | B1: OrderDate | C1: RequiredDate | D1: Corrected OD | E1: Correct RD | F1: Lead Time | G1: Region | H1: Country | I1: City | J1: CustomerSegment | K1: Channel | L1: Salesperson | M1: ProductCategory | N1: SKU | O1: UnitCost | P1: UnitPrice | Q1: DiscountPct | R1: Quantity
A2: ORD-2024-275203 | B2: 45362 | C2: 45388 | D2: =IF(C2>B2,B2,C2) -> 45362 | E2: =IF(C2>B2,C2,B2) -> 45388 | F2: =DATEDIF(D2,E2,"d") -> 26 | G2: Africa | H2: Kenya | I2: Kisumu | J2: Corporate | K2: Retail | L2: C. Otieno | M2: Components | N2: CMP-8270 | O2: 279.24 | P2: 608.9 | Q2: 0.112 | R2: 9
A3: ORD-2024-358795 | B3: 45588 | C3: 45587 | D3: =IF(C3>B3,B3,C3) -> 45587 | E3: =IF(C3>B3,C3,B3) -> 45588 | F3: =DATEDIF(D3,E3,"d") -> 1 | G3: Africa | H3: Nigeria | I3: Port Harcourt | J3: Education | K3: Online | L3: J. Njeri | M3: Printers | N3: PRN-9322 | O3: 1084.39 | P3: 759.33 | Q3: 0.237 | R3: 31
A4: ORD-2023-373538 | B4: 44985 | C4: 45010 | D4: =IF(C4>B4,B4,C4) -> 44985 | E4: =IF(C4>B4,C4,B4) -> 45010 | F4: =DATEDIF(D4,E4,"d") -> 25 | G4: Africa | H4: Kenya | I4: Nairobi | J4: Corporate | K4: Retail | L4: I. Johnson | M4: Networking | N4: NET-9666 | O4: 1460.76 | P4: -30.66 | Q4: 0.131 | R4: 12
A5: ORD-2025-168148 | B5: 45745 | C5: 45749 | D5: =IF(C5>B5,B5,C5) -> 45745 | E5: =IF(C5>B5,C5,B5) -> 45749 | F5: =DATEDIF(D5,E5,"d") -> 4 | G5: Africa | H5: Nigeria | I5: Lagos | J5: Non-Profit | K5: Marketplace | L5: G. Dubois | M5: Phones | N5: PHN-4556 | O5: 259.93 | P5: 255.94 | Q5: 0.072 | R5: 22
A6: ORD-2023-824839 | B6: 45266 | C6: 45291 | D6: =IF(C6>B6,B6,C6) -> 45266 | E6: =IF(C6>B6,C6,B6) -> 45291 | F6: =DATEDIF(D6,E6,"d") -> 25 | G6: Asia | H6: Japan | I6: Osaka | J6: Consumer | K6: Retail | L6: L. Okafor | M6: Printers | N6: PRN-8041 | O6: 663.03 | P6: 813.51 | Q6: 0.102 | R6: 15
A7: ORD-2023-723587 | B7: 44928 | C7: 44931 | D7: =IF(C7>B7,B7,C7) -> 44928 | E7: =IF(C7>B7,C7,B7) -> 44931 | F7: =DATEDIF(D7,E7,"d") -> 3 | G7: Americas | H7: Canada | I7: Toronto | J7: Corporate | K7: Distributor | L7: B. Chen | M7: Laptops | N7: LAP-8555 | O7: 315.87 | P7: 591.68 | Q7: 0 | R7: 7
A8: ORD-2024-336584 | B8: 45653 | C8: 45671 | D8: =IF(C8>B8,B8,C8) -> 45653 | E8: =IF(C8>B8,C8,B8) -> 45671 | F8: =DATEDIF(D8,E8,"d") -> 18 | G8: Asia | H8: India | I8: Bengaluru | J8: Small Business | K8: Marketplace | L8: E. Garcia | M8: Monitors | N8: MON-8629 | O8: 586.07 | P8: 845.97 | Q8: 0.147 | R8: 4
A9: ORD-2023-112666 | B9: 44941 | C9: 44939 | D9: =IF(C9>B9,B9,C9) -> 44939 | E9: =IF(C9>B9,C9,B9) -> 44941 | F9: =DATEDIF(D9,E9,"d") -> 2 | G9: Africa | H9: Nigeria | I9: Abuja | J9: Education | K9: Online | L9: O. Wang | M9: Printers | N9: PRN-6276 | O9: 28.38 | P9: 47.22 | Q9: 0.194 | R9: 18
A10: ORD-2024-589570 | B10: 45416 | C10: 45441 | D10: =IF(C10>B10,B10,C10) -> 45416 | E10: =IF(C10>B10,C10,B10) -> 45441 | F10: =DATEDIF(D10,E10,"d") -> 25 | G10: Africa | H10: Nigeria | I10: Abuja | J10: Non-Profit | K10: Marketplace | L10: O. Wang | M10: Monitors | N10: MON-6892 | O10: 1295.34 | P10: 2530.81 | Q10: 0.031 | R10: 6
A11: ORD-2025-997421 | B11: 45798 | C11: 45817 | D11: =IF(C11>B11,B11,C11) -> 45798 | E11: =IF(C11>B11,C11,B11) -> 45817 | F11: =DATEDIF(D11,E11,"d") -> 19 | G11: Americas | H11: Brazil | I11: São Paulo | J11: Non-Profit | K11: Online | L11: A. Patel | M11: Components | N11: CMP-3731 | O11: 1331.38 | P11: 2309.56 | Q11: 0.149 | R11: 31
A12: ORD-2024-210687 | B12: 45319 | C12: 45331 | D12: =IF(C12>B12,B12,C12) -> 45319 | E12: =IF(C12>B12,C12,B12) -> 45331 | F12: =DATEDIF(D12,E12,"d") -> 12 | G12: Europe | H12: Germany | I12: Berlin | J12: Corporate | K12: Online | L12: G. Dubois | M12: Accessories | N12: ACC-7938 | O12: 644.17 | P12: 700.12 | Q12: 0.006 | R12: 23
A13: ORD-2025-515515 | B13: 45660 | C13: 45680 | D13: =IF(C13>B13,B13,C13) -> 45660 | E13: =IF(C13>B13,C13,B13) -> 45680 | F13: =DATEDIF(D13,E13,"d") -> 20 | G13: Asia | H13: Japan | I13: Osaka | J13: Corporate | K13: Distributor | L13: F. Müller | M13: Phones | N13: PHN-7019 | O13: 908.6 | P13: 691.37 | Q13: 0.25 | R13: 20
... A34: ORD-2025-474710 | B34: 45862 | C34: 45875 | D34: =IF(C34>B34,B34,C34) -> 45862 | E34: =IF(C34>B34,C34,B34) -> 45875 | F34: =DATEDIF(D34,E34,"d") -> 13 | G34: Africa | H34: South Africa | I34: Johannesburg | J34: Education | K34: Marketplace | L34: D. Smith | M34: Networking | N34: NET-7966 | O34: 1463.9 | P34: 2633.02 | Q34: 0.084 | R34: 4
A35: ORD-2024-629525 | B35: 45400 | C35: 45420 | D35: =IF(C35>B35,B35,C35) -> 45400 | E35: =IF(C35>B35,C35,B35) -> 45420 | F35: =DATEDIF(D35,E35,"d") -> 20 | G35: Europe | H35: United Kingdom | I35: London | J35: Non-Profit | L35: D. Smith | M35: Laptops | N35: LAP-9932 | O35: 645.33 | P35: 1321.85 | Q35: 0 | R35: 10
A36: ORD-2024-167215 | B36: 45527 | C36: 45525 | D36: =IF(C36>B36,B36,C36) -> 45525 | E36: =IF(C36>B36,C36,B36) -> 45527 | F36: =DATEDIF(D36,E36,"d") -> 2 | G36: Africa | H36: South Africa | I36: Johannesburg | J36: Education | K36: Retail | L36: E. Garcia | M36: Components | N36: CMP-1559 | O36: 1432.52 | P36: 3036.87 | Q36: 0 | R36: 9
A37: ORD-2023-864121 | B37: 45012 | C37: 45038 | D37: =IF(C37>B37,B37,C37) -> 45012 | E37: =IF(C37>B37,C37,B37) -> 45038 | F37: =DATEDIF(D37,E37,"d") -> 26 | G37: Asia | H37: India | I37: Delhi | J37: Non-Profit | K37: Marketplace | L37: J. Njeri | M37: Printers | N37: PRN-4506 | O37: 178.53 | P37: 199.37 | Q37: 0.101 | R37: 37
A38: ORD-2024-692673 | B38: 45358 | C38: 45376 | D38: =IF(C38>B38,B38,C38) -> 45358 | E38: =IF(C38>B38,C38,B38) -> 45376 | F38: =DATEDIF(D38,E38,"d") -> 18 | G38: Europe | H38: Germany | I38: Munich | J38: Corporate | K38: Online | L38: B. Chen | M38: Components | N38: CMP-7617 | O38: 712.84 | P38: 927.51 | Q38: 0.243 | R38: 27
A39: ORD-2025-718992 | B39: 45832 | C39: 45848 | D39: =IF(C39>B39,B39,C39) -> 45832 | E39: =IF(C39>B39,C39,B39) -> 45848 | F39: =DATEDIF(D39,E39,"d") -> 16 | G39: Asia | H39: China | I39: Shanghai | J39: Enterprise | K39: Direct | L39: N. Brown | M39: Components | N39: CMP-8390 | O39: 757.19 | P39: 1735.41 | Q39: 0.136 | R39: 8
A40: ORD-2024-599522 | B40: 45401 | C40: 45418 | D40: =IF(C40>B40,B40,C40) -> 45401 | E40: =IF(C40>B40,C40,B40) -> 45418 | F40: =DATEDIF(D40,E40,"d") -> 17 | G40: Africa | H40: Nigeria | I40: Port Harcourt | J40: Non-Profit | K40: Online | L40: A. Patel | M40: Printers | N40: PRN-7303 | O40: 865.33 | P40: 1395.64 | Q40: 0.175 | R40: 13
A41: ORD-2023-651638 | B41: 45094 | C41: 45101 | D41: =IF(C41>B41,B41,C41) -> 45094 | E41: =IF(C41>B41,C41,B41) -> 45101 | F41: =DATEDIF(D41,E41,"d") -> 7 | G41: Americas | H41: USA | I41: San Francisco | J41: Corporate | K41: Retail | L41: I. Johnson | M41: Printers | N41: PRN-6536 | O41: 313.99 | P41: 454.42 | Q41: 0.129 | R41: 9
A42: ORD-2024-635626 | B42: 45531 | C42: 45554 | D42: =IF(C42>B42,B42,C42) -> 45531 | E42: =IF(C42>B42,C42,B42) -> 45554 | F42: =DATEDIF(D42,E42,"d") -> 23 | G42: Europe | H42: Germany | I42: Berlin | J42: Small Business | K42: Direct | L42: D. Smith | M42: Monitors | N42: MON-9967 | O42: 1024.01 | P42: 1580.97 | Q42: 0.037 | R42: 27
A43: ORD-2024-296582 | B43: 45302 | C43: 45324 | D43: =IF(C43>B43,B43,C43) -> 45302 | E43: =IF(C43>B43,C43,B43) -> 45324 | F43: =DATEDIF(D43,E43,"d") -> 22 | G43: Africa | H43: South Africa | I43: Durban | J43: Consumer | K43: Online | L43: K. Singh | M43: Networking | N43: NET-1412 | O43: 1206.2 | P43: 1759.79 | Q43: 0 | R43: 6
A44: ORD-2024-998320 | B44: 45590 | C44: 45610 | D44: =IF(C44>B44,B44,C44) -> 45590 | E44: =IF(C44>B44,C44,B44) -> 45610 | F44: =DATEDIF(D44,E44,"d") -> 20 | G44: Africa | H44: Kenya | I44: Mombasa | J44: Corporate | K44: Direct | L44: H. Kim | M44: Printers | N44: PRN-3143 | O44: 1396.48 | P44: 3204.5 | Q44: 0.318 | R44: 14
A45: ORD-2025-820255 | B45: 45806 | C45: 45828 | D45: =IF(C45>B45,B45,C45) -> 45806 | E45: =IF(C45>B45,C45,B45) -> 45828 | F45: =DATEDIF(D45,E45,"d") -> 22 | G45: Europe | H45: Germany | I45: Berlin | J45: Corporate | K45: Direct | L45: A. Patel | M45: Printers | N45: PRN-9787 | O45: 483.47 | P45: 1135.43 | Q45: 0.146 | R45: 11
A46: ORD-2024-389336 | B46: 45432 | C46: 45445 | D46: =IF(C46>B46,B46,C46) -> 45432 | E46: =IF(C46>B46,C46,B46) -> 45445 | F46: =DATEDIF(D46,E46,"d") -> 13 | G46: Americas | H46: Canada | I46: Vancouver | J46: Enterprise | K46: Marketplace | L46: K. Singh | M46: Components | N46: CMP-5946 | O46: 675.43 | P46: 996.36 | Q46: 0.182 | R46: 22
A47: ORD-2023-308124 | B47: 45035 | C47: 45046 | D47: =IF(C47>B47,B47,C47) -> 45035 | E47: =IF(C47>B47,C47,B47) -> 45046 | F47: =DATEDIF(D47,E47,"d") -> 11 | G47: Asia | H47: India | I47: Delhi | J47: Small Business | K47: Retail | L47: A. Patel | M47: Networking | N47: NET-2062 | O47: 826.55 | P47: 1397.05 | Q47: 0.169 | R47: 28
... A77: ORD-2023-722117 | B77: 45187 | C77: 45207 | D77: =IF(C77>B77,B77,C77) -> 45187 | E77: =IF(C77>B77,C77,B77) -> 45207 | F77: =DATEDIF(D77,E77,"d") -> 20 | G77: Asia | H77: India | I77: Delhi | J77: Small Business | K77: Direct | L77: B. Chen | M77: Components | N77: CMP-1009 | O77: 825.64 | P77: 1108.43 | Q77: 0.114 | R77: 7
A78: ORD-2024-446699 | B78: 45532 | C78: 45560 | D78: =IF(C78>B78,B78,C78) -> 45532 | E78: =IF(C78>B78,C78,B78) -> 45560 | F78: =DATEDIF(D78,E78,"d") -> 28 | G78: Americas | H78: Brazil | I78: Rio de Janeiro | J78: Non-Profit | K78: Online | M78: Accessories | N78: ACC-4490 | O78: 1394.65 | P78: 3144.1 | Q78: 0.134 | R78: 13
A79: ORD-2024-451005 | B79: 45473 | C79: 45471 | D79: =IF(C79>B79,B79,C79) -> 45471 | E79: =IF(C79>B79,C79,B79) -> 45473 | F79: =DATEDIF(D79,E79,"d") -> 2 | G79: Americas | H79: Brazil | I79: Rio de Janeiro | J79: Small Business | K79: Direct | L79: L. Okafor | M79: Accessories | N79: ACC-9162 | O79: 1112.98 | P79: 2095.73 | Q79: 0.072 | R79: 17
A80: ORD-2023-290279 | B80: 45091 | C80: 45093 | D80: =IF(C80>B80,B80,C80) -> 45091 | E80: =IF(C80>B80,C80,B80) -> 45093 | F80: =DATEDIF(D80,E80,"d") -> 2 | G80: Europe | H80: United Kingdom | I80: Manchester | J80: Non-Profit | K80: Direct | L80: K. Singh | M80: Components | N80: CMP-5820 | O80: 357.36 | P80: 703.62 | Q80: 0.257 | R80: 20
A81: ORD-2024-192263 | B81: 45617 | C81: 45647 | D81: =IF(C81>B81,B81,C81) -> 45617 | E81: =IF(C81>B81,C81,B81) -> 45647 | F81: =DATEDIF(D81,E81,"d") -> 30 | G81: Europe | H81: France | I81: Marseille | J81: Small Business | K81: Direct | L81: I. Johnson | M81: Monitors | N81: MON-7943 | O81: 1122.68 | P81: 1997.19 | Q81: 0.186 | R81: 3
A82: ORD-2023-159379 | B82: 44965 | C82: 44968 | D82: =IF(C82>B82,B82,C82) -> 44965 | E82: =IF(C82>B82,C82,B82) -> 44968 | F82: =DATEDIF(D82,E82,"d") -> 3 | G82: Africa | H82: South Africa | I82: Cape Town | J82: Corporate | K82: Direct | L82: M. Rossi | M82: Networking | N82: NET-5018 | O82: 1410.05 | P82: 2763.95 | Q82: 0.161 | R82: 26
A83: ORD-2023-343322 | B83: 45157 | C83: 45181 | D83: =IF(C83>B83,B83,C83) -> 45157 | E83: =IF(C83>B83,C83,B83) -> 45181 | F83: =DATEDIF(D83,E83,"d") -> 24 | G83: Americas | H83: Canada | I83: Vancouver | J83: Enterprise | K83: Retail | L83: I. Johnson | M83: Printers | N83: PRN-9669 | O83: 1183.95 | P83: 1503.53 | Q83: 0.241 | R83: 16
A84: ORD-2025-114382 | B84: 45791 | C84: 45801 | D84: =IF(C84>B84,B84,C84) -> 45791 | E84: =IF(C84>B84,C84,B84) -> 45801 | F84: =DATEDIF(D84,E84,"d") -> 10 | G84: Europe | H84: France | I84: Paris | J84: Small Business | K84: Marketplace | L84: K. Singh | M84: Components | N84: CMP-2865 | O84: 170.39 | P84: 388.04 | Q84: 0.084 | R84: 15
A85: ORD-2025-488349 | B85: 45770 | C85: 45769 | D85: =IF(C85>B85,B85,C85) -> 45769 | E85: =IF(C85>B85,C85,B85) -> 45770 | F85: =DATEDIF(D85,E85,"d") -> 1 | G85: Americas | H85: USA | I85: San Francisco | J85: Non-Profit | K85: Distributor | L85: D. Smith | M85: Monitors | N85: MON-3371 | O85: 23.24 | P85: 44.57 | Q85: 0.215 | R85: 15
A86: ORD-2025-330203 | B86: 45741 | C86: 45764 | D86: =IF(C86>B86,B86,C86) -> 45741 | E86: =IF(C86>B86,C86,B86) -> 45764 | F86: =DATEDIF(D86,E86,"d") -> 23 | G86: Europe | H86: United Kingdom | I86: London | J86: Consumer | K86: Retail | L86: H. Kim | M86: Networking | N86: NET-7166 | O86: 1421.19 | P86: 1808.26 | Q86: 0.104 | R86: 13
A87: ORD-2023-841426 | B87: 45282 | C87: 45283 | D87: =IF(C87>B87,B87,C87) -> 45282 | E87: =IF(C87>B87,C87,B87) -> 45283 | F87: =DATEDIF(D87,E87,"d") -> 1 | G87: Africa | H87: South Africa | I87: Cape Town | J87: Non-Profit | K87: Marketplace | L87: D. Smith | M87: Components | N87: CMP-4531 | O87: 1186.18 | P87: 1285.09 | Q87: 0.07 | R87: 11
A88: ORD-2024-594592 | B88: 45388 | C88: 45407 | D88: =IF(C88>B88,B88,C88) -> 45388 | E88: =IF(C88>B88,C88,B88) -> 45407 | F88: =DATEDIF(D88,E88,"d") -> 19 | G88: Asia | H88: China | I88: Shanghai | J88: Corporate | K88: Retail | L88: K. Singh | M88: Components | N88: CMP-8196 | O88: 1366.48 | P88: 1678.14 | Q88: 0.154 | R88: 10
A89: ORD-2025-863978 | B89: 45876 | C89: 45888 | D89: =IF(C89>B89,B89,C89) -> 45876 | E89: =IF(C89>B89,C89,B89) -> 45888 | F89: =DATEDIF(D89,E89,"d") -> 12 | G89: Africa | H89: Kenya | I89: Nakuru | J89: Corporate | L89: M. Rossi | M89: Components | N89: CMP-2854 | O89: 601.51 | P89: 679.35 | Q89: 0.188 | R89: 3
...

Sheet Cohort Analysis
A3: Sum of GrossRevenue | B3: Column Labels
A4: Row Labels | B4: 10-2023 | C4: 11-2023 | D4: 11-2024 | E4: 1-2023 | F4: 1-2024 | G4: 1-2025 | H4: 12-2023 | I4: 2-2023 | J4: 2-2024 | K4: 2-2025 | L4: 3-2023 | M4: 3-2025 | N4: 4-2023 | O4: 4-2024 | P4: 4-2025 | Q4: 5-2023 | R4: 5-2024 | S4: 5-2025 | T4: 6-2023 | U4: 6-2024 | V4: 7-2023 | W4: 7-2024 | X4: 7-2025 | Y4: 8-2023 | Z4: 8-2024 | AA4: 8-2025 | AB4: 9-2023 | AC4: 9-2024 | AD4: 9-2025 | AE4: Grand Total
A5: Brazil | B5: 16213.633 | C5: 24161.263 | D5: 11939.431 | E5: 1801.4076 | F5: 8567.3925 | G5: 22987.328 | H5: 61471.697 | I5: 24894.431 | J5: 39349.347 | K5: 70563.592 | L5: 24523.007 | M5: 16257.34 | N5: 12248.676 | O5: 57491.063 | P5: 68920.107 | Q5: 27194.152 | R5: 9469.7678 | S5: 69324.366 | T5: 46991.747 | U5: 41658.527 | V5: 93430.735 | W5: 10937.52 | X5: 38096.184 | Y5: 37330.003 | Z5: 41358.42 | AA5: 45754.744 | AB5: 7071.6331 | AC5: 85419.018 | AD5: 24172.045 | AE5: 1039598.6
A6: Grand Total | B6: 16213.633 | C6: 24161.263 | D6: 11939.431 | E6: 1801.4076 | F6: 8567.3925 | G6: 22987.328 | H6: 61471.697 | I6: 24894.431 | J6: 39349.347 | K6: 70563.592 | L6: 24523.007 | M6: 16257.34 | N6: 12248.676 | O6: 57491.063 | P6: 68920.107 | Q6: 27194.152 | R6: 9469.7678 | S6: 69324.366 | T6: 46991.747 | U6: 41658.527 | V6: 93430.735 | W6: 10937.52 | X6: 38096.184 | Y6: 37330.003 | Z6: 41358.42 | AA6: 45754.744 | AB6: 7071.6331 | AC6: 85419.018 | AD6: 24172.045 | AE6: 1039598.6

Sheet ABC Analysis
A3: Row Labels | B3: Sum of GrossRevenue
A4: Accessories | B4: 1349164.2
A5: ACC-6626 | B5: 79082.507
A6: ACC-2988 | B6: 53034.364
A7: ACC-9283 | B7: 46450.26
A8: ACC-9533 | B8: 43084.872
A9: ACC-8098 | B9: 38096.184 | G9: A = Top 80%
A10: ACC-4490 | B10: 35396.278 | G10: B = Next 15%
A11: ACC-7838 | B11: 35167.745 | G11: C = Last 5%
A12: ACC-1238 | B12: 34583.174
A13: ACC-5177 | B13: 34139.16
A14: ACC-9162 | B14: 33062.236
A15: ACC-7078 | B15: 32086.376
A16: ACC-1375 | B16: 31513.085
A17: ACC-1659 | B17: 28386.016
A18: ACC-6223 | B18: 26765.04
A19: ACC-4631 | B19: 26759.288
A20: ACC-5334 | B20: 26552.603
A21: ACC-6594 | B21: 24278.849
A22: ACC-9644 | B22: 23668.56
A23: ACC-8557 | B23: 23375.594
... A641: Grand Total | B641: 10986198

Sheet Sales Productivity
A3: Row Labels | B3: Sum of GrossRevenue | C3: Sum of GrossProfit | D3: Count of OrderID
A4: B. Chen | B4: 893735.66 | C4: 315969.97 | D4: 48
A5: Grand Total | B5: 893735.66 | C5: 315969.97 | D5: 48

Sheet Service Level Proxy
A4: Row Labels | B4: Count of OrderID
A5: No | B5: 0.7278481
A6: Yes | B6: 0.2721519
A7: Grand Total | B7: 1

Sheet Price Compliance
A3: Row Labels | B3: Count of DiscountPct
A4: No | B4: 0.90909091
A5: Yes | B5: 0.090909091
A6: Grand Total | B6: 1

Sheet Revenue By Month
A3: Row Labels | B3: Sum of GrossRevenue
A4: 1 | B4: 33042.254
A5: 2 | B5: 57375.807
A6: 4 | B6: 18675.932
A7: 5 | B7: 6899.8805
A8: 6 | B8: 4804.4682
A9: 8 | B9: 41106.801
A10: 12 | B10: 30519.802
A11: Grand Total | B11: 192424.94

Sheet Profit by R and C
A3: Sum of GrossProfit | B3: Column Labels
A4: Row Labels | B4: Direct | C4: Distributor | D4: Marketplace | E4: Online | F4: Retail | G4: Unknown Channel | H4: Grand Total
A5: Europe | B5: 17682.527 | C5: 9388.5683 | D5: 16954.685 | E5: 14144.854 | F5: -16776.201 | G5: 6765.2 | H5: 48159.634
A6: Grand Total | B6: 17682.527 | C6: 9388.5683 | D6: 16954.685 | E6: 14144.854 | F6: -16776.201 | G6: 6765.2 | H6: 48159.634

Sheet Top 10 SKUs
A3: Row Labels | B3: Sum of GrossRevenue
A4: MON-9967 | B4: 41106.801
A5: PRN-9624 | B5: 31822.024
A6: NET-4491 | B6: 29673.454
A7: MON-4959 | B7: 25553.783
A8: ACC-3103 | B8: 23195.018
A9: LAP-9932 | B9: 13218.5
A10: LAP-4551 | B10: 9847.2359
A11: PRN-1725 | B11: 6899.8805
A12: PRN-5067 | B12: 5457.4317
A13: PHN-5383 | B13: 4804.4682
A14: Grand Total | B14: 191578.6

Sheet KPIs
A3: Sum of GrossRevenue | B3: Sum of GrossProfit | C3: Sum of CostOfGoods
A4: 929424.89 | B4: 331115.03 | C4: 598309.86
A9: Average of GrossRevenue | B9: Sum of ScenarioGrossRevenue | C9: Sum of ScenarioGrossProfit
A10: 18224.017 | B10: 1004031.4 | C10: 350677.04

Sheet Revenue Share
A3: Row Labels | B3: Sum of GrossRevenue
A4: Europe | B4: 929424.89
A5: Direct | B5: 440549.31
A6: Distributor | B6: 89682.392
A7: Marketplace | B7: 141258.17
A8: Online | B8: 188656.7
A9: Retail | B9: 69278.32
A10: Grand Total | B10: 929424.89

Sheet Staging Data
A1: OrderID | B1: OrderDate | C1: RequiredDate | D1: New Order Date | E1: New Required Date | F1: LeadTimeDays | G1: MMM-YYY | H1: Region | I1: Country | J1: City | K1: CustomerSegment | L1: Channel | M1: Salesperson | N1: ProductCategory | O1: SKU | P1: UnitCost | Q1: UnitPrice | R1: DiscountPct | S1: Quantity | T1: GrossRevenue | U1: CostOfGoods | V1: GrossProfit | W1: MarginPct | X1: QUARTERS | Y1: HIERARCY | Z1: Price Band | AA1: Order Year | AB1: Order Month | AC1: 7 Day Lead Time | AD1: Disct%>20 | AE1: ScenarioDiscount | AF1: ScenarioUnitCost | AG1: ScenarioQuantity | AH1: ScenarioGrossRevenue | AI1: ScenarioCostOfGoods | AJ1: ScenarioGrossProfit
A2: ORD-2024-275203 | B2: 45362 | C2: 45388 | D2: =IF(C2>B2,B2,C2) -> 45362 | E2: =IF(C2>B2,C2,B2) -> 45388 | F2: =DATEDIF(D2,E2,"D") -> 26 | G2: =CONCATENATE(MONTH(D2), "-",YEAR(D2)) -> 3-2024 | H2: Africa | I2: Kenya | J2: Kisumu | K2: Corporate | L2: Retail | M2: C. Otieno | N2: Components | O2: CMP-8270 | P2: 279.24 | Q2: 608.9 | R2: 0.112 | S2: 9 | T2: =(Q2*S2)*(1-R2) -> 4866.3288 | U2: =P2*S2 -> 2513.16 | V2: =T2-U2 -> 2353.1688 | W2: =IF(T2=0, 0,V2/T2) -> 0.48356141 | X2: =CONCATENATE(IF(MONTH(D2)<=3,"Q1", IF(MONTH(D2)<=6, "Q2", IF(MONTH(D2)<= 9, "Q3", "Q4"))), "-", YEAR(D2)) -> Q1-2024 | Y2: =CONCATENATE(H2," → ",I2," → ",J2) -> Africa → Kenya → Kisumu | Z2: =IF(Q2<=1193.97, "Low",IF(Q2<1912.05,"Medium", "High")) -> Low | AA2: =YEAR(D2) -> 2024 | AB2: =MONTH(D2) -> 3 | AC2: =IF(F2<=7,"Yes", "No") -> No | AD2: =IF(R2>20%,"Yes","No") -> No | AE2: =IF(Dashboard!$P$47>'Staging Data'!R2,'Staging Data'!R2,Dashboard!$P$47) -> 0.1 | AF2: =(100%+Dashboard!$P$48)*'Staging Data'!P2 -> 293.202 | AG2: =(100%+Dashboard!$P$49)*S2 -> 9.36 | AH2: =(Q2*AG2)*(1-AE2) -> 5129.3736 | AI2: =AF2*AG2 -> 2744.3707 | AJ2: =AH2-AI2 -> 2385.0029
A3: ORD-2024-358795 | B3: 45588 | C3: 45587 | D3: =IF(C3>B3,B3,C3) -> 45587 | E3: =IF(C3>B3,C3,B3) -> 45588 | F3: =DATEDIF(D3,E3,"D") -> 1 | G3: =CONCATENATE(MONTH(D3), "-",YEAR(D3)) -> 10-2024 | H3: Africa | I3: Nigeria | J3: Port Harcourt | K3: Education | L3: Online | M3: J. Njeri | N3: Printers | O3: PRN-9322 | P3: 1084.39 | Q3: 759.33 | R3: 0.237 | S3: 31 | T3: =(Q3*S3)*(1-R3) -> 17960.432 | U3: =P3*S3 -> 33616.09 | V3: =T3-U3 -> -15655.658 | W3: =IF(T3=0, 0,V3/T3) -> -0.87167486 | X3: =CONCATENATE(IF(MONTH(D3)<=3,"Q1", IF(MONTH(D3)<=6, "Q2", IF(MONTH(D3)<= 9, "Q3", "Q4"))), "-", YEAR(D3)) -> Q4-2024 | Y3: =CONCATENATE(H3," → ",I3," → ",J3) -> Africa → Nigeria → Port Harcourt | Z3: =IF(Q3<=1193.97, "Low",IF(Q3<1912.05,"Medium", "High")) -> Low | AA3: =YEAR(D3) -> 2024 | AB3: =MONTH(D3) -> 10 | AC3: =IF(F3<=7,"Yes", "No") -> Yes | AD3: =IF(R3>20%,"Yes","No") -> Yes | AE3: =IF(Dashboard!$P$47>'Staging Data'!R3,'Staging Data'!R3,Dashboard!$P$47) -> 0.1 | AF3: =(100%+Dashboard!$P$48)*'Staging Data'!P3 -> 1138.6095 | AG3: =(100%+Dashboard!$P$49)*S3 -> 32.24 | AH3: =(Q3*AG3)*(1-AE3) -> 22032.719 | AI3: =AF3*AG3 -> 36708.77 | AJ3: =AH3-AI3 -> -14676.051
A4: ORD-2023-373538 | B4: 44985 | C4: 45010 | D4: =IF(C4>B4,B4,C4) -> 44985 | E4: =IF(C4>B4,C4,B4) -> 45010 | F4: =DATEDIF(D4,E4,"D") -> 25 | G4: =CONCATENATE(MONTH(D4), "-",YEAR(D4)) -> 2-2023 | H4: Africa | I4: Kenya | J4: Nairobi | K4: Corporate | L4: Retail | M4: I. Johnson | N4: Networking | O4: NET-9666 | P4: 1460.76 | Q4: 30.66 | R4: 0.131 | S4: 12 | T4: =(Q4*S4)*(1-R4) -> 319.72248 | U4: =P4*S4 -> 17529.12 | V4: =T4-U4 -> -17209.398 | W4: =IF(T4=0, 0,V4/T4) -> -53.826048 | X4: =CONCATENATE(IF(MONTH(D4)<=3,"Q1", IF(MONTH(D4)<=6, "Q2", IF(MONTH(D4)<= 9, "Q3", "Q4"))), "-", YEAR(D4)) -> Q1-2023 | Y4: =CONCATENATE(H4," → ",I4," → ",J4) -> Africa → Kenya → Nairobi | Z4: =IF(Q4<=1193.97, "Low",IF(Q4<1912.05,"Medium", "High")) -> Low | AA4: =YEAR(D4) -> 2023 | AB4: =MONTH(D4) -> 2 | AC4: =IF(F4<=7,"Yes", "No") -> No | AD4: =IF(R4>20%,"Yes","No") -> No | AE4: =IF(Dashboard!$P$47>'Staging Data'!R4,'Staging Data'!R4,Dashboard!$P$47) -> 0.1 | AF4: =(100%+Dashboard!$P$48)*'Staging Data'!P4 -> 1533.798 | AG4: =(100%+Dashboard!$P$49)*S4 -> 12.48 | AH4: =(Q4*AG4)*(1-AE4) -> 344.37312 | AI4: =AF4*AG4 -> 19141.799 | AJ4: =AH4-AI4 -> -18797.426
A5: ORD-2025-168148 | B5: 45745 | C5: 45749 | D5: =IF(C5>B5,B5,C5) -> 45745 | E5: =IF(C5>B5,C5,B5) -> 45749 | F5: =DATEDIF(D5,E5,"D") -> 4 | G5: =CONCATENATE(MONTH(D5), "-",YEAR(D5)) -> 3-2025 | H5: Africa | I5: Nigeria | J5: Lagos | K5: Non-Profit | L5: Marketplace | M5: G. Dubois | N5: Phones | O5: PHN-4556 | P5: 259.93 | Q5: 255.94 | R5: 0.072 | S5: 22 | T5: =(Q5*S5)*(1-R5) -> 5225.271 | U5: =P5*S5 -> 5718.46 | V5: =T5-U5 -> -493.18896 | W5: =IF(T5=0, 0,V5/T5) -> -0.094385335 | X5: =CONCATENATE(IF(MONTH(D5)<=3,"Q1", IF(MONTH(D5)<=6, "Q2", IF(MONTH(D5)<= 9, "Q3", "Q4"))), "-", YEAR(D5)) -> Q1-2025 | Y5: =CONCATENATE(H5," → ",I5," → ",J5) -> Africa → Nigeria → Lagos | Z5: =IF(Q5<=1193.97, "Low",IF(Q5<1912.05,"Medium", "High")) -> Low | AA5: =YEAR(D5) -> 2025 | AB5: =MONTH(D5) -> 3 | AC5: =IF(F5<=7,"Yes", "No") -> Yes | AD5: =IF(R5>20%,"Yes","No") -> No | AE5: =IF(Dashboard!$P$47>'Staging Data'!R5,'Staging Data'!R5,Dashboard!$P$47) -> 0.072 | AF5: =(100%+Dashboard!$P$48)*'Staging Data'!P5 -> 272.9265 | AG5: =(100%+Dashboard!$P$49)*S5 -> 22.88 | AH5: =(Q5*AG5)*(1-AE5) -> 5434.2819 | AI5: =AF5*AG5 -> 6244.5583 | AJ5: =AH5-AI5 -> -810.27644
A6: ORD-2023-824839 | B6: 45266 | C6: 45291 | D6: =IF(C6>B6,B6,C6) -> 45266 | E6: =IF(C6>B6,C6,B6) -> 45291 | F6: =DATEDIF(D6,E6,"D") -> 25 | G6: =CONCATENATE(MONTH(D6), "-",YEAR(D6)) -> 12-2023 | H6: Asia | I6: Japan | J6: Osaka | K6: Consumer | L6: Retail | M6: L. Okafor | N6: Printers | O6: PRN-8041 | P6: 663.03 | Q6: 813.51 | R6: 0.102 | S6: 15 | T6: =(Q6*S6)*(1-R6) -> 10957.98 | U6: =P6*S6 -> 9945.45 | V6: =T6-U6 -> 1012.5297 | W6: =IF(T6=0, 0,V6/T6) -> 0.092401129 | X6: =CONCATENATE(IF(MONTH(D6)<=3,"Q1", IF(MONTH(D6)<=6, "Q2", IF(MONTH(D6)<= 9, "Q3", "Q4"))), "-", YEAR(D6)) -> Q4-2023 | Y6: =CONCATENATE(H6," → ",I6," → ",J6) -> Asia → Japan → Osaka | Z6: =IF(Q6<=1193.97, "Low",IF(Q6<1912.05,"Medium", "High")) -> Low | AA6: =YEAR(D6) -> 2023 | AB6: =MONTH(D6) -> 12 | AC6: =IF(F6<=7,"Yes", "No") -> No | AD6: =IF(R6>20%,"Yes","No") -> No | AE6: =IF(Dashboard!$P$47>'Staging Data'!R6,'Staging Data'!R6,Dashboard!$P$47) -> 0.1 | AF6: =(100%+Dashboard!$P$48)*'Staging Data'!P6 -> 696.1815 | AG6: =(100%+Dashboard!$P$49)*S6 -> 15.6 | AH6: =(Q6*AG6)*(1-AE6) -> 11421.68 | AI6: =AF6*AG6 -> 10860.431 | AJ6: =AH6-AI6 -> 561.249
A7: ORD-2023-723587 | B7: 44928 | C7: 44931 | D7: =IF(C7>B7,B7,C7) -> 44928 | E7: =IF(C7>B7,C7,B7) -> 44931 | F7: =DATEDIF(D7,E7,"D") -> 3 | G7: =CONCATENATE(MONTH(D7), "-",YEAR(D7)) -> 1-2023 | H7: Americas | I7: Canada | J7: Toronto | K7: Corporate | L7: Distributor | M7: B. Chen | N7: Laptops | O7: LAP-8555 | P7: 315.87 | Q7: 591.68 | R7: 0 | S7: 7 | T7: =(Q7*S7)*(1-R7) -> 4141.76 | U7: =P7*S7 -> 2211.09 | V7: =T7-U7 -> 1930.67 | W7: =IF(T7=0, 0,V7/T7) -> 0.46614724 | X7: =CONCATENATE(IF(MONTH(D7)<=3,"Q1", IF(MONTH(D7)<=6, "Q2", IF(MONTH(D7)<= 9, "Q3", "Q4"))), "-", YEAR(D7)) -> Q1-2023 | Y7: =CONCATENATE(H7," → ",I7," → ",J7) -> Americas → Canada → Toronto | Z7: =IF(Q7<=1193.97, "Low",IF(Q7<1912.05,"Medium", "High")) -> Low | AA7: =YEAR(D7) -> 2023 | AB7: =MONTH(D7) -> 1 | AC7: =IF(F7<=7,"Yes", "No") -> Yes | AD7: =IF(R7>20%,"Yes","No") -> No | AE7: =IF(Dashboard!$P$47>'Staging Data'!R7,'Staging Data'!R7,Dashboard!$P$47) -> 0 | AF7: =(100%+Dashboard!$P$48)*'Staging Data'!P7 -> 331.6635 | AG7: =(100%+Dashboard!$P$49)*S7 -> 7.28 | AH7: =(Q7*AG7)*(1-AE7) -> 4307.4304 | AI7: =AF7*AG7 -> 2414.5103 | AJ7: =AH7-AI7 -> 1892.9201
A8: ORD-2024-336584 | B8: 45653 | C8: 45671 | D8: =IF(C8>B8,B8,C8) -> 45653 | E8: =IF(C8>B8,C8,B8) -> 45671 | F8: =DATEDIF(D8,E8,"D") -> 18 | G8: =CONCATENATE(MONTH(D8), "-",YEAR(D8)) -> 12-2024 | H8: Asia | I8: India | J8: Bengaluru | K8: Small Business | L8: Marketplace | M8: E. Garcia | N8: Monitors | O8: MON-8629 | P8: 586.07 | Q8: 845.97 | R8: 0.147 | S8: 4 | T8: =(Q8*S8)*(1-R8) -> 2886.4496 | U8: =P8*S8 -> 2344.28 | V8: =T8-U8 -> 542.16964 | W8: =IF(T8=0, 0,V8/T8) -> 0.1878327 | X8: =CONCATENATE(IF(MONTH(D8)<=3,"Q1", IF(MONTH(D8)<=6, "Q2", IF(MONTH(D8)<= 9, "Q3", "Q4"))), "-", YEAR(D8)) -> Q4-2024 | Y8: =CONCATENATE(H8," → ",I8," → ",J8) -> Asia → India → Bengaluru | Z8: =IF(Q8<=1193.97, "Low",IF(Q8<1912.05,"Medium", "High")) -> Low | AA8: =YEAR(D8) -> 2024 | AB8: =MONTH(D8) -> 12 | AC8: =IF(F8<=7,"Yes", "No") -> No | AD8: =IF(R8>20%,"Yes","No") -> No | AE8: =IF(Dashboard!$P$47>'Staging Data'!R8,'Staging Data'!R8,Dashboard!$P$47) -> 0.1 | AF8: =(100%+Dashboard!$P$48)*'Staging Data'!P8 -> 615.3735 | AG8: =(100%+Dashboard!$P$49)*S8 -> 4.16 | AH8: =(Q8*AG8)*(1-AE8) -> 3167.3117 | AI8: =AF8*AG8 -> 2559.9538 | AJ8: =AH8-AI8 -> 607.35792
A9: ORD-2023-112666 | B9: 44941 | C9: 44939 | D9: =IF(C9>B9,B9,C9) -> 44939 | E9: =IF(C9>B9,C9,B9) -> 44941 | F9: =DATEDIF(D9,E9,"D") -> 2 | G9: =CONCATENATE(MONTH(D9), "-",YEAR(D9)) -> 1-2023 | H9: Africa | I9: Nigeria | J9: Abuja | K9: Education | L9: Online | M9: O. Wang | N9: Printers | O9: PRN-6276 | P9: 28.38 | Q9: 47.22 | R9: 0.194 | S9: 18 | T9: =(Q9*S9)*(1-R9) -> 685.06776 | U9: =P9*S9 -> 510.84 | V9: =T9-U9 -> 174.22776 | W9: =IF(T9=0, 0,V9/T9) -> 0.25432194 | X9: =CONCATENATE(IF(MONTH(D9)<=3,"Q1", IF(MONTH(D9)<=6, "Q2", IF(MONTH(D9)<= 9, "Q3", "Q4"))), "-", YEAR(D9)) -> Q1-2023 | Y9: =CONCATENATE(H9," → ",I9," → ",J9) -> Africa → Nigeria → Abuja | Z9: =IF(Q9<=1193.97, "Low",IF(Q9<1912.05,"Medium", "High")) -> Low | AA9: =YEAR(D9) -> 2023 | AB9: =MONTH(D9) -> 1 | AC9: =IF(F9<=7,"Yes", "No") -> Yes | AD9: =IF(R9>20%,"Yes","No") -> No | AE9: =IF(Dashboard!$P$47>'Staging Data'!R9,'Staging Data'!R9,Dashboard!$P$47) -> 0.1 | AF9: =(100%+Dashboard!$P$48)*'Staging Data'!P9 -> 29.799 | AG9: =(100%+Dashboard!$P$49)*S9 -> 18.72 | AH9: =(Q9*AG9)*(1-AE9) -> 795.56256 | AI9: =AF9*AG9 -> 557.83728 | AJ9: =AH9-AI9 -> 237.72528
A10: ORD-2024-589570 | B10: 45416 | C10: 45441 | D10: =IF(C10>B10,B10,C10) -> 45416 | E10: =IF(C10>B10,C10,B10) -> 45441 | F10: =DATEDIF(D10,E10,"D") -> 25 | G10: =CONCATENATE(MONTH(D10), "-",YEAR(D10)) -> 5-2024 | H10: Africa | I10: Nigeria | J10: Abuja | K10: Non-Profit | L10: Marketplace | M10: O. Wang | N10: Monitors | O10: MON-6892 | P10: 1295.34 | Q10: 2530.81 | R10: 0.031 | S10: 6 | T10: =(Q10*S10)*(1-R10) -> 14714.129 | U10: =P10*S10 -> 7772.04 | V10: =T10-U10 -> 6942.0893 | W10: =IF(T10=0, 0,V10/T10) -> 0.47179749 | X10: =CONCATENATE(IF(MONTH(D10)<=3,"Q1", IF(MONTH(D10)<=6, "Q2", IF(MONTH(D10)<= 9, "Q3", "Q4"))), "-", YEAR(D10)) -> Q2-2024 | Y10: =CONCATENATE(H10," → ",I10," → ",J10) -> Africa → Nigeria → Abuja | Z10: =IF(Q10<=1193.97, "Low",IF(Q10<1912.05,"Medium", "High")) -> High | AA10: =YEAR(D10) -> 2024 | AB10: =MONTH(D10) -> 5 | AC10: =IF(F10<=7,"Yes", "No") -> No | AD10: =IF(R10>20%,"Yes","No") -> No | AE10: =IF(Dashboard!$P$47>'Staging Data'!R10,'Staging Data'!R10,Dashboard!$P$47) -> 0.031 | AF10: =(100%+Dashboard!$P$48)*'Staging Data'!P10 -> 1360.107 | AG10: =(100%+Dashboard!$P$49)*S10 -> 6.24 | AH10: =(Q10*AG10)*(1-AE10) -> 15302.695 | AI10: =AF10*AG10 -> 8487.0677 | AJ10: =AH10-AI10 -> 6815.6268
A11: ORD-2023-856322 | B11: 44955 | C11: 44963 | D11: =IF(C11>B11,B11,C11) -> 44955 | E11: =IF(C11>B11,C11,B11) -> 44963 | F11: =DATEDIF(D11,E11,"D") -> 8 | G11: =CONCATENATE(MONTH(D11), "-",YEAR(D11)) -> 1-2023 | H11: Americas | I11: Brazil | J11: Brasília | K11: Corporate | L11: Marketplace | M11: D. Smith | N11: Monitors | O11: MON-7207 | P11: 41.84 | Q11: 86.2 | R11: 0.226 | S11: 27 | T11: =(Q11*S11)*(1-R11) -> 1801.4076 | U11: =P11*S11 -> 1129.68 | V11: =T11-U11 -> 671.7276 | W11: =IF(T11=0, 0,V11/T11) -> 0.3728904 | X11: =CONCATENATE(IF(MONTH(D11)<=3,"Q1", IF(MONTH(D11)<=6, "Q2", IF(MONTH(D11)<= 9, "Q3", "Q4"))), "-", YEAR(D11)) -> Q1-2023 | Y11: =CONCATENATE(H11," → ",I11," → ",J11) -> Americas → Brazil → Brasília | Z11: =IF(Q11<=1193.97, "Low",IF(Q11<1912.05,"Medium", "High")) -> Low | AA11: =YEAR(D11) -> 2023 | AB11: =MONTH(D11) -> 1 | AC11: =IF(F11<=7,"Yes", "No") -> No | AD11: =IF(R11>20%,"Yes","No") -> Yes | AE11: =IF(Dashboard!$P$47>'Staging Data'!R11,'Staging Data'!R11,Dashboard!$P$47) -> 0.1 | AF11: =(100%+Dashboard!$P$48)*'Staging Data'!P11 -> 43.932 | AG11: =(100%+Dashboard!$P$49)*S11 -> 28.08 | AH11: =(Q11*AG11)*(1-AE11) -> 2178.4464 | AI11: =AF11*AG11 -> 1233.6106 | AJ11: =AH11-AI11 -> 944.83584
A12: ORD-2024-901115 | B12: 45498 | C12: 45506 | D12: =IF(C12>B12,B12,C12) -> 45498 | E12: =IF(C12>B12,C12,B12) -> 45506 | F12: =DATEDIF(D12,E12,"D") -> 8 | G12: =CONCATENATE(MONTH(D12), "-",YEAR(D12)) -> 7-2024 | H12: Americas | I12: Canada | J12: Montreal | K12: Consumer | L12: Direct | M12: J. Njeri | N12: Accessories | O12: ACC-6626 | P12: 986.81 | Q12: 2050.31 | R12: 0.103 | S12: 43 | T12: =(Q12*S12)*(1-R12) -> 79082.507 | U12: =P12*S12 -> 42432.83 | V12: =T12-U12 -> 36649.677 | W12: =IF(T12=0, 0,V12/T12) -> 0.46343595 | X12: =CONCATENATE(IF(MONTH(D12)<=3,"Q1", IF(MONTH(D12)<=6, "Q2", IF(MONTH(D12)<= 9, "Q3", "Q4"))), "-", YEAR(D12)) -> Q3-2024 | Y12: =CONCATENATE(H12," → ",I12," → ",J12) -> Americas → Canada → Montreal | Z12: =IF(Q12<=1193.97, "Low",IF(Q12<1912.05,"Medium", "High")) -> High | AA12: =YEAR(D12) -> 2024 | AB12: =MONTH(D12) -> 7 | AC12: =IF(F12<=7,"Yes", "No") -> No | AD12: =IF(R12>20%,"Yes","No") -> No | AE12: =IF(Dashboard!$P$47>'Staging Data'!R12,'Staging Data'!R12,Dashboard!$P$47) -> 0.1 | AF12: =(100%+Dashboard!$P$48)*'Staging Data'!P12 -> 1036.1505 | AG12: =(100%+Dashboard!$P$49)*S12 -> 44.72 | AH12: =(Q12*AG12)*(1-AE12) -> 82520.877 | AI12: =AF12*AG12 -> 46336.65 | AJ12: =AH12-AI12 -> 36184.227
A13: ORD-2025-515515 | B13: 45660 | C13: 45680 | D13: =IF(C13>B13,B13,C13) -> 45660 | E13: =IF(C13>B13,C13,B13) -> 45680 | F13: =DATEDIF(D13,E13,"D") -> 20 | G13: =CONCATENATE(MONTH(D13), "-",YEAR(D13)) -> 1-2025 | H13: Asia | I13: Japan | J13: Osaka | K13: Corporate | L13: Distributor | M13: F. Müller | N13: Phones | O13: PHN-7019 | P13: 908.6 | Q13: 691.37 | R13: 0.25 | S13: 20 | T13: =(Q13*S13)*(1-R13) -> 10370.55 | U13: =P13*S13 -> 18172 | V13: =T13-U13 -> -7801.45 | W13: =IF(T13=0, 0,V13/T13) -> -0.75226965 | X13: =CONCATENATE(IF(MONTH(D13)<=3,"Q1", IF(MONTH(D13)<=6, "Q2", IF(MONTH(D13)<= 9, "Q3", "Q4"))), "-", YEAR(D13)) -> Q1-2025 | Y13: =CONCATENATE(H13," → ",I13," → ",J13) -> Asia → Japan → Osaka | Z13: =IF(Q13<=1193.97, "Low",IF(Q13<1912.05,"Medium", "High")) -> Low | AA13: =YEAR(D13) -> 2025 | AB13: =MONTH(D13) -> 1 | AC13: =IF(F13<=7,"Yes", "No") -> No | AD13: =IF(R13>20%,"Yes","No") -> Yes | AE13: =IF(Dashboard!$P$47>'Staging Data'!R13,'Staging Data'!R13,Dashboard!$P$47) -> 0.1 | AF13: =(100%+Dashboard!$P$48)*'Staging Data'!P13 -> 954.03 | AG13: =(100%+Dashboard!$P$49)*S13 -> 20.8 | AH13: =(Q13*AG13)*(1-AE13) -> 12942.446 | AI13: =AF13*AG13 -> 19843.824 | AJ13: =AH13-AI13 -> -6901.3776
... A633: ORD-2025-728935 | B633: 45716 | C633: 45726 | D633: =IF(C633>B633,B633,C633) -> 45716 | E633: =IF(C633>B633,C633,B633) -> 45726 | F633: =DATEDIF(D633,E633,"D") -> 10 | G633: =CONCATENATE(MONTH(D633), "-",YEAR(D633)) -> 2-2025 | H633: Asia | I633: Japan | J633: Osaka | K633: Education | L633: Distributor | M633: N. Brown | N633: Laptops | O633: LAP-3017 | P633: 51.86 | Q633: 45.98 | R633: 0.173 | S633: 7 | T633: =(Q633*S633)*(1-R633) -> 266.17822 | U633: =P633*S633 -> 363.02 | V633: =T633-U633 -> -96.84178 | W633: =IF(T633=0, 0,V633/T633) -> -0.36382308 | X633: =CONCATENATE(IF(MONTH(D633)<=3,"Q1", IF(MONTH(D633)<=6, "Q2", IF(MONTH(D633)<= 9, "Q3", "Q4"))), "-", YEAR(D633)) -> Q1-2025 | Y633: =CONCATENATE(H633," → ",I633," → ",J633) -> Asia → Japan → Osaka | Z633: =IF(Q633<=1193.97, "Low",IF(Q633<1912.05,"Medium", "High")) -> Low | AA633: =YEAR(D633) -> 2025 | AB633: =MONTH(D633) -> 2 | AC633: =IF(F633<=7,"Yes", "No") -> No | AD633: =IF(R633>20%,"Yes","No") -> No | AE633: =IF(Dashboard!$P$47>'Staging Data'!R633,'Staging Data'!R633,Dashboard!$P$47) -> 0.1 | AF633: =(100%+Dashboard!$P$48)*'Staging Data'!P633 -> 54.453 | AG633: =(100%+Dashboard!$P$49)*S633 -> 7.28 | AH633: =(Q633*AG633)*(1-AE633) -> 301.26096 | AI633: =AF633*AG633 -> 396.41784 | AJ633: =AH633-AI633 -> -95.15688

Sheet README
A1: The duplicates have been highlighted in red colour.
A2: The data has been formatted to the correct data types i.e orderdate and requireddate to dates, numbers to numbers, unit cost to currency, SKU to text, quantity to number etc..
A3: Blanks have been replaced with: unknown city, unknown salesperson and unknown channel for the respective columns
A4: Negative unit values were identified and converted to positive values.
A5: Identified the discount percentage >30 and replaced them with null and then calculated the mean and replaced the nulls mean
A6: Used IF to swap required dates that were earlier than order date. Then generated the lead time (required date-ordered date)
A7: Utilised Quartile function and divided unit prices based on 25th, 50th and 75th quantiles to develop price bands.
A8: A pivot table to show the first month a specific country appeared on the orders and the gross revenue for that month.
A9: ABC analysis was done and colours were assigned to different classes i.e A - Blue, B - Green and C - Orange
A10: Asales productivity pivot table has been created to show salespersons with the highest orders overall.
A11: A revenue share pivot table has been created and a pie chart was used to visualize sales per region using different channels in Africa and Asia, the retail channel dominated while in America and Europe the online channel dominated
A12: A scenario panel has been created on the dashboard with its own KPIs.
... A18: In Europe, the retail channel made losses

Sheet Brief
A1: Assignment
A2: Excel Mastery Assignment: Sales Operations & Analytics
A4: Overview:
A5: You are an analyst for a multi-regional electronics distributor. The 'Data' sheet contains 632 rows and 15 columns of transactional data with intentional data-quality issues.
A6: Your job is to clean, enrich, analyze, and present insights via a dynamic dashboard.
A8: Part A — Data Cleaning & Preparation:
A9: 1) Create a staging table where you:
A10: • Remove exact duplicate rows (define and document your duplicate criteria).
A11: • Fix data types (dates as Dates, numeric fields as numbers).
A12: • Handle missing values for City, Salesperson, and Channel using reasonable business logic (document your approach).
A13: • Flag and correct suspicious UnitPrice values (e.g., negative prices) and discounts (e.g., > 30%).
A14: • Ensure RequiredDate is not earlier than OrderDate; where it is, impute a corrected RequiredDate (explain your rule).
... A67: 15) Ensure your dashboard responds to slicers without broken references.

Sheet Dashboard
J12: GROSS REVENUE | M12: TOTAL GROSS PROFIT | O12: ON TIME % | Q12: AVERAGE GROSS REVENUE
J13: =GETPIVOTDATA("Sum of GrossRevenue",KPIs!$A$3) -> 929424.89 | M13: =GETPIVOTDATA("Sum of GrossProfit",KPIs!$A$3) -> 331115.03 | O13: =GETPIVOTDATA("OrderID",'Service Level Proxy'!$A$4,"7 Day Lead Time","Yes") -> 0.2721519 | Q13: =GETPIVOTDATA("Average of GrossRevenue",KPIs!$A$9) -> 18224.017
O42: SCENARIO GROSS REVENUE | P42: SCENARIO GROSS PROFIT
O43: =GETPIVOTDATA("Sum of ScenarioGrossRevenue",KPIs!$A$9) -> 1004031.4 | P43: =GETPIVOTDATA("Sum of ScenarioGrossProfit",KPIs!$A$9) -> 350677.04
O47: Global Discount Cap (e.g., 0%–25%). | P47: 0.1
O48: UnitCost inflation factor (e.g., 0%–15%). | P48: 0.05
O49: Quantity uplift (e.g., 0%–20%). | P49: 0.04
